<?xml version="1.0" encoding="utf-8"?>
<!-- This URDF was automatically created by SolidWorks to URDF Exporter! Originally created by Stephen Brawner (brawner@gmail.com) 
     Commit Version: 1.6.0-4-g7f85cfe  Build Version: 1.6.7995.38578
     For more information, please see http://wiki.ros.org/sw_urdf_exporter -->
<robot
  name="ur33">
  <link
    name="base_link">
    <inertial>
      <origin
        xyz="3.93116168057694E-05 -0.000808491080125994 0.046220310995705"
        rpy="0 0 0" />
      <mass
        value="0.615785283013905" />
      <inertia
        ixx="0.000761300764311582"
        ixy="2.98963200654777E-07"
        ixz="3.53676883539917E-07"
        iyy="0.000774576499049897"
        iyz="-3.46585976118834E-06"
        izz="0.00100294058166069" />
    </inertial>
    <visual>
      <origin
        xyz="0 0 0"
        rpy="0 0 0" />
      <geometry>
        <mesh
          filename="package://ur33/meshes/base_link.STL" />
      </geometry>
      <material
        name="">
        <color
          rgba="0.752941176470588 0.752941176470588 0.752941176470588 1" />
      </material>
    </visual>
    <collision>
      <origin
        xyz="0 0 0"
        rpy="0 0 0" />
      <geometry>
        <mesh
          filename="package://ur33/meshes/base_link.STL" />
      </geometry>
    </collision>
  </link>
  <link
    name="link1">
    <inertial>
      <origin
        xyz="-0.00625089745310523 0.00384444461112433 0.140320421113684"
        rpy="0 0 0" />
      <mass
        value="0.755651972571794" />
      <inertia
        ixx="0.00101180434870827"
        ixy="3.52300925244213E-05"
        ixz="0.000111752432382906"
        iyy="0.00104735230146711"
        iyz="-6.84846356621434E-05"
        izz="0.000906485139777163" />
    </inertial>
    <visual>
      <origin
        xyz="0 0 0"
        rpy="0 0 0" />
      <geometry>
        <mesh
          filename="package://ur33/meshes/link1.STL" />
      </geometry>
      <material
        name="">
        <color
          rgba="0.752941176470588 0.752941176470588 0.752941176470588 1" />
      </material>
    </visual>
    <collision>
      <origin
        xyz="0 0 0"
        rpy="0 0 0" />
      <geometry>
        <mesh
          filename="package://ur33/meshes/link1.STL" />
      </geometry>
    </collision>
  </link>
  <joint
    name="joint1"
    type="continuous">
    <origin
      xyz="0 0 0"
      rpy="0 0 0" />
    <parent
      link="base_link" />
    <child
      link="link1" />
    <axis
      xyz="0 0 -1" />
    <limit
      lower="-3.14"
      upper="3.14"
      effort="100"
      velocity="2" />
  </joint>
  <link
    name="link2">
    <inertial>
      <origin
        xyz="-0.0614610231996296 0.0860061627704666 0.116589773897471"
        rpy="0 0 0" />
      <mass
        value="1.80164817391607" />
      <inertia
        ixx="0.0023186116671055"
        ixy="0.000463522536300758"
        ixz="4.72188440614429E-05"
        iyy="0.0020010695774144"
        iyz="-6.59248325584966E-05"
        izz="0.0025172679877967" />
    </inertial>
    <visual>
      <origin
        xyz="0 0 0"
        rpy="0 0 0" />
      <geometry>
        <mesh
          filename="package://ur33/meshes/link2.STL" />
      </geometry>
      <material
        name="">
        <color
          rgba="0.752941176470588 0.752941176470588 0.752941176470588 1" />
      </material>
    </visual>
    <collision>
      <origin
        xyz="0 0 0"
        rpy="0 0 0" />
      <geometry>
        <mesh
          filename="package://ur33/meshes/link2.STL" />
      </geometry>
    </collision>
  </link>
  <joint
    name="joint2"
    type="continuous">
    <origin
      xyz="0 0 0.1519"
      rpy="1.5708 0 -2.1213" />
    <parent
      link="link1" />
    <child
      link="link2" />
    <axis
      xyz="0 0 -1" />
    <limit
      lower="-3.14"
      upper="3.14"
      effort="100"
      velocity="2" />
  </joint>
  <link
    name="link3">
    <inertial>
      <origin
        xyz="0.0848721525553792 -0.0718523582365145 0.0880667755483855"
        rpy="0 0 0" />
      <mass
        value="0.962318952715275" />
      <inertia
        ixx="0.000763928216708484"
        ixy="0.000261390958396011"
        ixz="-3.51942093732436E-05"
        iyy="0.000851454207568593"
        iyz="2.97876397293877E-05"
        izz="0.00101486278864245" />
    </inertial>
    <visual>
      <origin
        xyz="0 0 0"
        rpy="0 0 0" />
      <geometry>
        <mesh
          filename="package://ur33/meshes/link3.STL" />
      </geometry>
      <material
        name="">
        <color
          rgba="0.752941176470588 0.752941176470588 0.752941176470588 1" />
      </material>
    </visual>
    <collision>
      <origin
        xyz="0 0 0"
        rpy="0 0 0" />
      <geometry>
        <mesh
          filename="package://ur33/meshes/link3.STL" />
      </geometry>
    </collision>
  </link>
  <joint
    name="joint3"
    type="continuous">
    <origin
      xyz="-0.14167 0.19823 0.11985"
      rpy="3.1416 0 0.6205" />
    <parent
      link="link2" />
    <child
      link="link3" />
    <axis
      xyz="0 0 1" />
    <limit
      lower="-3.14"
      upper="3.14"
      effort="100"
      velocity="2" />
  </joint>
  <link
    name="link4">
    <inertial>
      <origin
        xyz="0.000131209888373479 0.000500927513799487 0.0774753212040768"
        rpy="0 0 0" />
      <mass
        value="0.325313468041478" />
      <inertia
        ixx="0.000224305930807925"
        ixy="-6.96758128022657E-06"
        ixz="4.88606687222132E-06"
        iyy="0.000201017702186723"
        iyz="1.76869754838883E-05"
        izz="0.000194599789764272" />
    </inertial>
    <visual>
      <origin
        xyz="0 0 0"
        rpy="0 0 0" />
      <geometry>
        <mesh
          filename="package://ur33/meshes/link4.STL" />
      </geometry>
      <material
        name="">
        <color
          rgba="0.752941176470588 0.752941176470588 0.752941176470588 1" />
      </material>
    </visual>
    <collision>
      <origin
        xyz="0 0 0"
        rpy="0 0 0" />
      <geometry>
        <mesh
          filename="package://ur33/meshes/link4.STL" />
      </geometry>
    </collision>
  </link>
  <joint
    name="joint4"
    type="continuous">
    <origin
      xyz="0.16257 -0.13762 0.093211"
      rpy="3.1416 0 -2.2733" />
    <parent
      link="link3" />
    <child
      link="link4" />
    <axis
      xyz="0 0 1" />
    <limit
      lower="-3.14"
      upper="3.14"
      effort="100"
      velocity="2" />
  </joint>
  <link
    name="link5">
    <inertial>
      <origin
        xyz="0.000112522115200631 -0.0774757537365017 -0.000505090488728377"
        rpy="0 0 0" />
      <mass
        value="0.325304141773555" />
      <inertia
        ixx="0.000225095056299192"
        ixy="-3.76400572536212E-06"
        ixz="5.44701372646168E-06"
        iyy="0.000194601314147715"
        iyz="1.79591798255415E-05"
        izz="0.000200244518504051" />
    </inertial>
    <visual>
      <origin
        xyz="0 0 0"
        rpy="0 0 0" />
      <geometry>
        <mesh
          filename="package://ur33/meshes/link5.STL" />
      </geometry>
      <material
        name="">
        <color
          rgba="0.752941176470588 0.752941176470588 0.752941176470588 1" />
      </material>
    </visual>
    <collision>
      <origin
        xyz="0 0 0"
        rpy="0 0 0" />
      <geometry>
        <mesh
          filename="package://ur33/meshes/link5.STL" />
      </geometry>
    </collision>
  </link>
  <joint
    name="joint5"
    type="continuous">
    <origin
      xyz="0 0 0.0834"
      rpy="0 0 -0.26969" />
    <parent
      link="link4" />
    <child
      link="link5" />
    <axis
      xyz="0 -1 0" />
    <limit
      lower="-3.14"
      upper="3.14"
      effort="100"
      velocity="2" />
  </joint>
  <link
    name="link6">
    <inertial>
      <origin
        xyz="3.75217964138641E-05 -9.6258702699914E-05 0.0619729046967783"
        rpy="0 0 0" />
      <mass
        value="0.115355209052266" />
      <inertia
        ixx="4.24968269717473E-05"
        ixy="-7.19665046883362E-08"
        ixz="-3.74817081762432E-08"
        iyy="4.26533940599609E-05"
        iyz="9.61768604574672E-08"
        izz="5.90666201317261E-05" />
    </inertial>
    <visual>
      <origin
        xyz="0 0 0"
        rpy="0 0 0" />
      <geometry>
        <mesh
          filename="package://ur33/meshes/link6.STL" />
      </geometry>
      <material
        name="">
        <color
          rgba="0.752941176470588 0.752941176470588 0.752941176470588 1" />
      </material>
    </visual>
    <collision>
      <origin
        xyz="0 0 0"
        rpy="0 0 0" />
      <geometry>
        <mesh
          filename="package://ur33/meshes/link6.STL" />
      </geometry>
    </collision>
  </link>
  <joint
    name="joint6"
    type="continuous">
    <origin
      xyz="0 -0.0834 0"
      rpy="0 -0.20651 0" />
    <parent
      link="link5" />
    <child
      link="link6" />
    <axis
      xyz="0 0 1" />
    <limit
      lower="-3.14"
      upper="3.14"
      effort="100"
      velocity="2" />
  </joint>
</robot>